<?xml version="1.0" encoding="utf-8"?>
<!-- This URDF was automatically created by SolidWorks to URDF Exporter! Originally created by Stephen Brawner (brawner@gmail.com) 
     Commit Version: 1.6.0-1-g15f4949  Build Version: 1.6.7594.29634
     For more information, please see http://wiki.ros.org/sw_urdf_exporter -->
<robot name="schunk_gripper">
  <link name="schunk_base">
    <inertial>
      <origin xyz="-1.077E-05 6.258E-06 0.039649" rpy="0 0 0" />
      <mass value="0.2131" />
      <inertia ixx="0.00012179" ixy="-4.0513E-10" ixz="-6.591E-08" iyy="0.00013676" iyz="-6.5304E-08" izz="3.9709E-05" />
    </inertial>
    <visual>
      <origin xyz="0 0 0" rpy="0 0 0" />
      <geometry>
        <mesh filename="package://rosi_schunk/mesh/gripper/schunk_base.STL" />
      </geometry>
      <material name="base">
        <color rgba="0.3 0.3 0.3 1" />
      </material>
    </visual>
    <collision>
      <origin xyz="0 0 0" rpy="0 0 0" />
      <geometry>
        <mesh filename="package://rosi_schunk/mesh/gripper/schunk_base.STL" />
      </geometry>
    </collision>
  </link>
  <link name="finger1_link">
    <inertial>
      <origin xyz="0.00058603 0.0043154 -0.013212" rpy="0 0 0" />
      <mass value="0.029378" />
      <inertia ixx="4.0686E-06" ixy="-3.3521E-07" ixz="-3.5289E-07" iyy="3.104E-06" iyz="-9.9133E-07" izz="1.6826E-06" />
    </inertial>
    <visual>
      <origin xyz="0 0 0" rpy="0 0 0" />
      <geometry>
        <mesh filename="package://rosi_schunk/mesh/gripper/finger1_link.STL" />
      </geometry>
      <material name="finger_1">
        <color rgba="1 0 0 1" />
      </material>
    </visual>
    <collision>
      <origin xyz="0 0 0" rpy="0 0 0" />
      <geometry>
        <mesh filename="package://rosi_schunk/mesh/gripper/finger1_link.STL" />
      </geometry>
    </collision>
  </link>
  <joint name="finger1_joint" type="prismatic">
    <origin xyz="0.02 -0.004 0.08105" rpy="1.5708 0 1.5708" />
    <parent link="schunk_base" />
    <child link="finger1_link" />
    <axis xyz="0 0 1" />
    <limit lower="-0.006" upper="0" effort="72.5" velocity="0.03" />
    <dynamics damping="1" friction="0.7" />
  </joint>
  <link name="finger2_link">
    <inertial>
      <origin xyz="0.00057261 0.020203 -0.0042166" rpy="0 0 0" />
      <mass value="0.030067" />
      <inertia ixx="4.0801E-06" ixy="-3.5289E-07" ixz="3.3521E-07" iyy="1.6839E-06" iyz="9.9133E-07" izz="3.1154E-06" />
    </inertial>
    <visual>
      <origin xyz="0 0 0" rpy="0 0 0" />
      <geometry>
        <mesh filename="package://rosi_schunk/mesh/gripper/finger2_link.STL" />
      </geometry>
      <material name="">
        <color rgba="1 1 0 1" />
      </material>
    </visual>
    <collision>
      <origin xyz="0 0 0" rpy="0 0 0" />
      <geometry>
        <mesh filename="package://rosi_schunk/mesh/gripper/finger2_link.STL" />
      </geometry>
    </collision>
  </link>
  <joint name="finger2_joint" type="prismatic">
    <origin xyz="0.014 0.004 0.08105" rpy="3.1416 0 -1.5708" />
    <parent link="schunk_base" />
    <child link="finger2_link" />
    <axis xyz="0 -1 0" />
    <limit lower="0" upper="0.006" effort="72.5" velocity="0.03" />
    <dynamics damping="1" friction="0.7" />
  </joint>
  <link name="sensor_link">
    <inertial>
      <origin xyz="-0.0002 -0.006 -0.0029709" rpy="0 0 0" />
      <mass value="0.0033492" />
      <inertia ixx="5.2951E-08" ixy="-1.0699E-24" ixz="3.1019E-25" iyy="5.9138E-08" iyz="2.4492E-24" izz="8.629E-08" />
    </inertial>
    <visual>
      <origin xyz="0 0 0" rpy="0 0 0" />
      <geometry>
        <mesh filename="package://rosi_schunk/mesh/gripper/sensor_link.STL" />
      </geometry>
      <material name="black">
        <color rgba="0.1 0.1 0.1 1" />
      </material>
    </visual>
    <collision>
      <origin xyz="0 0 0" rpy="0 0 0" />
      <geometry>
        <mesh filename="package://rosi_schunk/mesh/gripper/sensor_link.STL" />
      </geometry>
    </collision>
  </link>
  <joint name="sensor_joint" type="fixed">
    <origin xyz="0.02 -0.0002 0.0696" rpy="1.5708 0 -1.5708" />
    <parent link="schunk_base" />
    <child link="sensor_link" />
    <axis xyz="0 0 0" />
  </joint>
  <link name="cable_link">
    <inertial>
      <origin xyz="0.003294 -1.5548E-05 4.1316E-19" rpy="0 0 0" />
      <mass value="0.0012007" />
      <inertia ixx="1.3722E-08" ixy="7.5124E-11" ixz="1.6062E-24" iyy="1.426E-08" iyz="7.6952E-25" izz="1.4226E-08" />
    </inertial>
    <visual>
      <origin xyz="0 0 0" rpy="0 0 0" />
      <geometry>
        <mesh filename="package://rosi_schunk/mesh/gripper/cable_link.STL" />
      </geometry>
      <material name="cable">
        <color rgba="0.6 0.6 0.6 1" />
      </material>
    </visual>
    <collision>
      <origin xyz="0 0 0" rpy="0 0 0" />
      <geometry>
        <mesh filename="package://rosi_schunk/mesh/gripper/cable_link.STL" />
      </geometry>
    </collision>
  </link>
  <joint name="cable_joint" type="fixed">
    <origin xyz="0.0197 0 0.0214" rpy="-1.5708 0 0" />
    <parent link="schunk_base" />
    <child link="cable_link" />
    <axis xyz="0 0 0" />
  </joint>
  <link name="logo_link">
    <inertial>
      <origin xyz="-7.3017E-05 2.7193E-08 0.00014611" rpy="0 0 0" />
      <mass value="0.00015603" />
      <inertia ixx="9.9395E-10" ixy="1.5837E-12" ixz="1.4684E-12" iyy="6.528E-09" iyz="-5.4684E-16" izz="7.5197E-09" />
    </inertial>
    <visual>
      <origin xyz="0 0 0" rpy="0 0 0" />
      <geometry>
        <mesh filename="package://rosi_schunk/mesh/gripper/logo_link.STL" />
      </geometry>
      <material name="logo">
        <color rgba="0.0 0.0 0.7 1" />
      </material>
    </visual>
    <collision>
      <origin xyz="0 0 0" rpy="0 0 0" />
      <geometry>
        <mesh filename="package://rosi_schunk/mesh/gripper/logo_link.STL" />
      </geometry>
    </collision>
  </link>
  <joint name="logo_joint" type="fixed">
    <origin xyz="0 0.0129 0.03915" rpy="-1.5708 0 0" />
    <parent link="schunk_base" />
    <child link="logo_link" />
    <axis xyz="0 0 0" />
  </joint>

  <transmission name="finger1_transmission">
    <type>transmission_interface/SimpleTransmission</type>
    <actuator name="finger1_motor" />
    <joint name="finger1_joint">
        <hardwareInterface>hardware_interface/PositionJointInterface</hardwareInterface>
    </joint>
  </transmission>
  <transmission name="finger2_transmission">
    <type>transmission_interface/SimpleTransmission</type>
    <actuator name="finger2_motor" />
    <joint name="finger2_joint">
        <hardwareInterface>hardware_interface/PositionJointInterface</hardwareInterface>
    </joint>
  </transmission>
</robot>